Workbook

Sheet Wave 2 2025
A1: Review number | B1: Survey report | C1: Short branch name | D1: Result | E1: Branch Area | F1: Jenis Toko | G1: Kota | H1: Regional | I1: KPI | J1: Site Code
A2: 1081166 | C2: ST EG OL DAAN MOGOT TANGERANG | D2: 91.58 | E2: DKI 03 | F2: ST | G2: Tangerang | H2: REG 01 | I2: 4.6 | J2: =_xlfn.XLOOKUP(C2,Master!C:C,Master!B:B) -> 2130
A3: 1081180 | C3: ST EG YOGYA 4 COKROAMINOG | D3: 79.40 | E3: JATENG 01 | F3: ST | G3: Yogyakarta | H3: REG 03 | I3: 3.95 | J3: =_xlfn.XLOOKUP(C3,Master!C:C,Master!B:B) -> 2070
A4: 1081188 | C4: ST EG OL BUAH BATU BANDUNG | D4: 81.25 | E4: JABAR 02 | F4: ST | G4: Bandung | H4: REG 02 | I4: 4.05 | J4: =_xlfn.XLOOKUP(C4,Master!C:C,Master!B:B) -> 2041
A5: 1081184 | C5: SH AEON MALL SENTUL | D5: 71.75 | E5: DKI 04 | F5: SH | G5: Bogor | H5: REG 01 | I5: 3.6 | J5: =_xlfn.XLOOKUP(C5,Master!C:C,Master!B:B) -> 5159
A6: 1081195 | C6: ST EG UJUNG BERUNG BANDUNG | D6: 92.83 | E6: JABAR 02 | F6: ST | G6: Bandung | H6: REG 02 | I6: 4.65 | J6: =_xlfn.XLOOKUP(C6,Master!C:C,Master!B:B) -> 2007
A7: 1081198 | C7: ST EG KALIMALANG JAKTIM | D7: 81.55 | E7: DKI 02 | F7: ST | G7: Jakarta Timur | H7: REG 01 | I7: 4.1 | J7: =_xlfn.XLOOKUP(C7,Master!C:C,Master!B:B) -> 2269
A8: 1081200 | C8: ST EG CITEUREUP BOGOR | D8: 89.87 | E8: DKI 04 | F8: ST | G8: Bogor | H8: REG 01 | I8: 4.5 | J8: =_xlfn.XLOOKUP(C8,Master!C:C,Master!B:B) -> 2240
A9: 1081202 | C9: ST EG PANAM PEKANBARU | D9: 82.36 | E9: SUM 02 | F9: ST | G9: Pekanbaru | H9: REG 03 | I9: 4.1 | J9: =_xlfn.XLOOKUP(C9,Master!C:C,Master!B:B) -> 7024
A10: 1081221 | C10: ST EG KEBUMEN | D10: 80.97 | E10: JATENG 01 | F10: ST | G10: Kebumen | H10: REG 03 | I10: 4.05 | J10: =_xlfn.XLOOKUP(C10,Master!C:C,Master!B:B) -> 2152
A11: 1081230 | C11: ST EG MAJAPAHIT SEMARANG | D11: 93.41 | E11: JATENG 02 | F11: ST | G11: Semarang | H11: REG 03 | I11: 4.65 | J11: =_xlfn.XLOOKUP(C11,Master!C:C,Master!B:B) -> 2108
A12: 1081214 | C12: SH EG MALL SKA PEKANBARU | D12: 80.13 | E12: SUM 02 | F12: SH | G12: Pekanbaru | H12: REG 03 | I12: 4 | J12: =_xlfn.XLOOKUP(C12,Master!C:C,Master!B:B) -> 5052
A13: 1081219 | C13: ST EG CIMAHI UTARA | D13: 91.62 | E13: JABAR 04 | F13: ST | G13: Cimahi | H13: REG 02 | I13: 4.6 | J13: =_xlfn.XLOOKUP(C13,Master!C:C,Master!B:B) -> 7032
... A274: 1087641 | C274: ST EG LETJ SUPRATO TEBING TINGGI | D274: 84.68 | E274: SUM 03 | F274: ST | G274: Tebing Tinggi | H274: REG 03 | I274: 4.25 | J274: =_xlfn.XLOOKUP(C274,Master!C:C,Master!B:B) -> 2241

Sheet Wave 1 2025
A1: Review number | B1: Survey report | C1: Short branch name | D1: Result | E1: Branch Area | F1: Jenis Toko | G1: Kota | H1: Regional | I1: KPI | J1: Site Code
A2: 1056145 | C2: ST EG KALIMALANG JAKTIM | D2: 80.80 | E2: DKI 02 | F2: ST | G2: Jakarta Timur | H2: REG 01 | I2: 4.05 | J2: =_xlfn.XLOOKUP(C2,Master!C:C,Master!B:B) -> 2269
A3: 1055690 | C3: ST EG PURWOREJO | D3: 72.19 | E3: JATENG 01 | F3: ST | G3: Kabupaten Purworejo | H3: REG 03 | I3: 3.6 | J3: =_xlfn.XLOOKUP(C3,Master!C:C,Master!B:B) -> 7017
A4: 1056015 | C4: ST EG OL KEMANGGISAN JAKARTA | D4: 65.93 | E4: DKI 01 | F4: ST | G4: Jakarta Barat | H4: REG 01 | I4: 3.3 | J4: =_xlfn.XLOOKUP(C4,Master!C:C,Master!B:B) -> 2135
A5: 1055760 | C5: ST EG TEHOK JAMBI | D5: 74.77 | E5: SUM 02 | F5: ST | G5: Jambi | H5: REG 03 | I5: 3.75 | J5: =_xlfn.XLOOKUP(C5,Master!C:C,Master!B:B) -> 2325
A6: 1055619 | C6: ST EG SURABAYA BARAT | D6: 67.26 | E6: JATIM 01 | F6: ST | G6: Surabaya | H6: REG 04 | I6: 3.35 | J6: =_xlfn.XLOOKUP(C6,Master!C:C,Master!B:B) -> 2219
A7: 1059090 | C7: ST EG BANDA ACEH | D7: 88.90 | E7: SUM 03 | F7: ST | G7: Banda Aceh | H7: REG 03 | I7: 4.45 | J7: =_xlfn.XLOOKUP(C7,Master!C:C,Master!B:B) -> 7040
A8: 1056046 | C8: ST EG OL BOGOR | D8: 75.39 | E8: DKI 04 | F8: ST | G8: Bogor | H8: REG 01 | I8: 3.75 | J8: =_xlfn.XLOOKUP(C8,Master!C:C,Master!B:B) -> 2013
A9: 1055857 | C9: ST EG ANTASARI LAMPUNG | D9: 83.01 | E9: SUM 01 | F9: ST | G9: Bandar Lampung | H9: REG 02 | I9: 4.15 | J9: =_xlfn.XLOOKUP(C9,Master!C:C,Master!B:B) -> 2225
A10: 1055707 | C10: ST EG CIMAHI UTARA | D10: 80.72 | E10: JABAR 04 | F10: ST | G10: Cimahi | H10: REG 02 | I10: 4.05 | J10: =_xlfn.XLOOKUP(C10,Master!C:C,Master!B:B) -> 7032
A11: 1057277 | C11: SH EG PARIS VAN JAVA BANDUNG | D11: 85.41 | E11: JABAR 01 | F11: SH | G11: Bandung | H11: REG 02 | I11: 4.25 | J11: =_xlfn.XLOOKUP(C11,Master!C:C,Master!B:B) -> 5148
A12: 1056034 | C12: ST EG OL MANYAR 2 | D12: 72.74 | E12: JATIM 01 | F12: ST | G12: Surabaya | H12: REG 04 | I12: 3.65 | J12: =_xlfn.XLOOKUP(C12,Master!C:C,Master!B:B) -> 2398
A13: 1056194 | C13: SH EG ATRIUM JAKARTA | D13: 82.97 | E13: DKI 01 | F13: SH | G13: Jakarta Pusat | H13: REG 01 | I13: 4.15 | J13: =_xlfn.XLOOKUP(C13,Master!C:C,Master!B:B) -> 5025
... A277: 1060604 | C277: ST EG MUARA BUNGO | D277: 58.14 | E277: SUM 02 | F277: ST | G277: Jambi | H277: REG 02 | I277: 2.9 | J277: =_xlfn.XLOOKUP(C277,Master!C:C,Master!B:B) -> 2354

Sheet Wave 3 2024
A1: Review number | B1: Survey report | C1: Short branch name | D1: Result | E1: Branch Area | F1: Jenis Toko | G1: Kota | H1: Regional | I1: KPI | J1: Site Code
A2: 1031804 | C2: ST EG RANGKASBITUNG | D2: 83.27 | E2: DKI 03 | F2: ST | G2: Rangkasbitung | H2: REG 01 | I2: 4.15 | J2: =_xlfn.XLOOKUP(C2,Master!C:C,Master!B:B) -> 2189
A3: 1031810 | C3: ST EG PANDEGLANG | D3: 84.89 | E3: DKI 03 | F3: ST | G3: Pandeglang | H3: REG 01 | I3: 4.25 | J3: =_xlfn.XLOOKUP(C3,Master!C:C,Master!B:B) -> 2176
A4: 1031412 | C4: ST EG MEDAN HALAT | D4: 75.50 | E4: SUM 03 | F4: ST | G4: Medan | H4: REG 03 | I4: 3.75 | J4: =_xlfn.XLOOKUP(C4,Master!C:C,Master!B:B) -> 2320
A5: 1031416 | C5: ST EG NGANJUK | D5: 97.78 | E5: JATIM 03 | F5: ST | G5: Nganjuk | H5: REG 04 | I5: 4.9 | J5: =_xlfn.XLOOKUP(C5,Master!C:C,Master!B:B) -> 7034
A6: 1031442 | C6: ST EG SIDOARJO | D6: 81.09 | E6: JATIM 01 | F6: ST | G6: Sidoarjo | H6: REG 04 | I6: 4.05 | J6: =_xlfn.XLOOKUP(C6,Master!C:C,Master!B:B) -> 2077
A7: 1031443 | C7: ST EG CEMENGKALANG SIDOARJO | D7: 91.46 | E7: JATIM 01 | F7: ST | G7: Sidoarjo | H7: REG 04 | I7: 4.55 | J7: =_xlfn.XLOOKUP(C7,Master!C:C,Master!B:B) -> 2330
A8: 1031445 | C8: ST EG WARU SIDOARJO | D8: 90.12 | E8: JATIM 01 | F8: ST | G8: Sidoarjo | H8: REG 04 | I8: 4.5 | J8: =_xlfn.XLOOKUP(C8,Master!C:C,Master!B:B) -> 2346
A9: 1031621 | C9: SH EG PARIS VAN JAVA BANDUNG | D9: 88.25 | E9: JABAR 01 | F9: SH | G9: Bandung | H9: REG 02 | I9: 4.4 | J9: =_xlfn.XLOOKUP(C9,Master!C:C,Master!B:B) -> 5148
A10: 1031651 | C10: ST EG CIREBON | D10: 88.56 | E10: JABAR 03 | F10: ST | G10: Cirebon | H10: REG 02 | I10: 4.45 | J10: =_xlfn.XLOOKUP(C10,Master!C:C,Master!B:B) -> 2015
A11: 1031662 | C11: ST EG SILIWANGI CIREBON | D11: 84.36 | E11: JABAR 03 | F11: ST | G11: Cirebon | H11: REG 02 | I11: 4.2 | J11: =_xlfn.XLOOKUP(C11,Master!C:C,Master!B:B) -> 2313
A12: 1031889 | C12: ST EG HANKAM BEKASI | D12: 94.24 | E12: DKI 02 | F12: ST | G12: Bekasi | H12: REG 01 | I12: 4.7 | J12: =_xlfn.XLOOKUP(C12,Master!C:C,Master!B:B) -> 2265
A13: 1032385 | C13: ST EG OL CIHAMPELAS BANDUNG | D13: 98.13 | E13: JABAR 01 | F13: ST | G13: Bandung | H13: REG 02 | I13: 4.9 | J13: =_xlfn.XLOOKUP(C13,Master!C:C,Master!B:B) -> 2004
A14: 1032414 | C14: ST EG CITEUREUP BOGOR | D14: 90.60 | E14: DKI 04 | F14: ST | G14: Bogor | H14: REG 01 | I14: 4.55 | J14: =_xlfn.XLOOKUP(C14,Master!C:C,Master!B:B) -> 2240
A15: 1032401 | C15: ST EG OL BOGOR | D15: 80.20 | E15: DKI 04 | F15: ST | G15: Bogor | H15: REG 01 | I15: 4 | J15: =_xlfn.XLOOKUP(C15,Master!C:C,Master!B:B) -> 2013
A16: 1032412 | C16: ST EG CIBINONG | D16: 88.75 | E16: DKI 04 | F16: ST | G16: Kabupaten Bogor | H16: REG 01 | I16: 4.45 | J16: =_xlfn.XLOOKUP(C16,Master!C:C,Master!B:B) -> 2365
A17: 1032470 | C17: ST EG CIPONDOH TANGERANG | D17: 89.84 | E17: DKI 03 | F17: ST | G17: Tangerang | H17: REG 01 | I17: 4.5 | J17: =_xlfn.XLOOKUP(C17,Master!C:C,Master!B:B) -> 2236
A18: 1032464 | C18: ST EG BOYOLALI | D18: 83.99 | E18: JATENG 01 | F18: ST | G18: Boyolali | H18: REG 03 | I18: 4.2 | J18: =_xlfn.XLOOKUP(C18,Master!C:C,Master!B:B) -> 7016
A19: 1032481 | C19: ST EG MT.HARYONO BALIKPAPAN | D19: 77.25 | E19: IBT 01 | F19: ST | G19: Balikpapan | H19: REG 05 | I19: 3.85 | J19: =_xlfn.XLOOKUP(C19,Master!C:C,Master!B:B) -> 7036
A20: 1032505 | C20: ST EG CINERE DEPOK | D20: 89.46 | E20: DKI 04 | F20: ST | G20: Depok | H20: REG 01 | I20: 4.45 | J20: =_xlfn.XLOOKUP(C20,Master!C:C,Master!B:B) -> 2187
A21: 1032493 | C21: ST EG HASANUDDIN GOWA | D21: 84.19 | E21: IBT 02 | F21: ST | G21: Gowa | H21: REG 03 | I21: 4.2 | J21: =_xlfn.XLOOKUP(C21,Master!C:C,Master!B:B) -> 2234
A22: 1032689 | C22: ST EG LHOKSEUMAWE | D22: 85.99 | E22: SUM 03 | F22: ST | G22: Lhokseumawe | H22: REG 03 | I22: 4.3 | J22: =_xlfn.XLOOKUP(C22,Master!C:C,Master!B:B) -> 2326
A23: 1032603 | C23: ST EG BANDUNG | D23: 85 | E23: JABAR 01 | F23: ST | G23: Bandung | H23: REG 02 | I23: 4.25 | J23: =_xlfn.XLOOKUP(C23,Master!C:C,Master!B:B) -> #N/A
A24: 1032947 | C24: ST EG GRAND DEPOK CITY | D24: 79.60 | E24: DKI 04 | F24: ST | G24: Depok | H24: REG 01 | I24: 4 | J24: =_xlfn.XLOOKUP(C24,Master!C:C,Master!B:B) -> 2393
A25: 1032515 | C25: ST EG PARUNG | D25: 87.15 | E25: DKI 04 | F25: ST | G25: Depok | H25: REG 01 | I25: 4.35 | J25: =_xlfn.XLOOKUP(C25,Master!C:C,Master!B:B) -> 2328
A26: 1032524 | C26: ST EG OL KELAPA GADING JAKARTA | D26: 87.98 | E26: DKI 01 | F26: ST | G26: Jakarta Utara | H26: REG 01 | I26: 4.4 | J26: =_xlfn.XLOOKUP(C26,Master!C:C,Master!B:B) -> 2122
A27: 1032535 | C27: ST EG JATI ASIH BEKASI | D27: 86.36 | E27: DKI 02 | F27: ST | G27: Bekasi | H27: REG 01 | I27: 4.3 | J27: =_xlfn.XLOOKUP(C27,Master!C:C,Master!B:B) -> 2178
A28: 1032545 | C28: ST EG LAKS LEO WATIMENA AMBON | D28: 87.46 | E28: IBT 04 | F28: ST | G28: Ambon | H28: REG 05 | I28: 4.35 | J28: =_xlfn.XLOOKUP(C28,Master!C:C,Master!B:B) -> 2300
A29: 1032530 | C29: ST EG OL SETIABUDHI BANDUNG | D29: 93.86 | E29: JABAR 01 | F29: ST | G29: Bandung | H29: REG 02 | I29: 4.7 | J29: =_xlfn.XLOOKUP(C29,Master!C:C,Master!B:B) -> 2009
A30: 1032529 | C30: ST EG SERPONG TANGERANG | D30: 57.59 | E30: DKI 03 | F30: ST | G30: Tangerang | H30: REG 01 | I30: 2.9 | J30: =_xlfn.XLOOKUP(C30,Master!C:C,Master!B:B) -> 7002
A31: 1032563 | C31: ST EG PATI | D31: 84.34 | E31: JATENG 02 | F31: ST | G31: Kabupaten Pati | H31: REG 03 | I31: 4.2 | J31: =_xlfn.XLOOKUP(C31,Master!C:C,Master!B:B) -> 7033
A32: 1032581 | C32: ST EG OL KALIURANG YOGYAKARTA | D32: 88.65 | E32: JATENG 01 | F32: ST | G32: Sleman | H32: REG 03 | I32: 4.45 | J32: =_xlfn.XLOOKUP(C32,Master!C:C,Master!B:B) -> 2038
A33: 1032559 | C33: ST EG SURABAYA | D33: 81.18 | E33: JATIM 01 | F33: ST | G33: Surabaya | H33: REG 04 | I33: 4.05 | J33: =_xlfn.XLOOKUP(C33,Master!C:C,Master!B:B) -> 2210
A34: 1031642 | C34: SH EG KOTA KASABLANCA JAKARTA | D34: 69.93 | E34: DKI 01 | F34: SH | G34: Jakarta Selatan | H34: REG 01 | I34: 3.5 | J34: =_xlfn.XLOOKUP(C34,Master!C:C,Master!B:B) -> 5026
A35: 1032615 | C35: SH AEON MALL SENTUL | D35: 87.89 | E35: DKI 04 | F35: SH | G35: Bogor | H35: REG 01 | I35: 4.4 | J35: =_xlfn.XLOOKUP(C35,Master!C:C,Master!B:B) -> 5159
A36: 1032704 | C36: ST EG BREBES | D36: 85.33 | E36: JATENG 02 | F36: ST | G36: Kabupaten Brebes | H36: REG 03 | I36: 4.25 | J36: =_xlfn.XLOOKUP(C36,Master!C:C,Master!B:B) -> 2318
... A60: 1032884 | C60: ST EG JEMBER | D60: 90.44 | E60: JATIM 02 | F60: ST | G60: Jember | H60: REG 04 | I60: 4.5 | J60: =_xlfn.XLOOKUP(C60,Master!C:C,Master!B:B) -> 2069
A61: 1032886 | C61: ST EG PENGAYOMAN MAKASAR | D61: 80.46 | E61: IBT 02 | F61: ST | G61: Makassar | H61: REG 05 | I61: 4 | J61: =_xlfn.XLOOKUP(C61,Master!C:C,Master!B:B) -> 2125
A62: 1032890 | C62: SH EG LIPPO PLAZA JEMBER | D62: 87.10 | E62: JATIM 02 | F62: SH | G62: Jember | H62: REG 04 | I62: 4.35 | J62: =_xlfn.XLOOKUP(C62,Master!C:C,Master!B:B) -> 5105
A63: 1032685 | C63: ST EG BITUNG | D63: 88.99 | E63: IBT 04 | F63: ST | G63: Bitung | H63: REG 05 | I63: 4.45 | J63: =_xlfn.XLOOKUP(C63,Master!C:C,Master!B:B) -> 2317
...

Sheet Wave 2 2024
A1: Review number | B1: Survey report | C1: Short branch name | D1: Result | E1: Branch Area | F1: Jenis Toko | G1: Kota | H1: Regional | I1: (760869) KPI | J1: Site Code
A2: 1014163 | C2: ST EG PADJ BOGOR | D2: 87.41 | E2: DKI 04 | F2: ST | G2: Bogor | H2: REG 01 | I2: 4.35 | J2: =_xlfn.XLOOKUP(C2,Master!C:C,Master!B:B) -> 2008
A3: 1013148 | C3: ST EG KARANG TENGAH JAKBAR | D3: 94.42 | E3: DKI 03 | F3: ST | G3: Tangerang | H3: REG 01 | I3: 4.7 | J3: =_xlfn.XLOOKUP(C3,Master!C:C,Master!B:B) -> #N/A
A4: 1012802 | C4: ST EG TEUKU UMAR BALI | D4: 85.79 | E4: IBT 03 | F4: ST | G4: Denpasar | H4: REG 05 | I4: 4.3 | J4: =_xlfn.XLOOKUP(C4,Master!C:C,Master!B:B) -> 2016
A5: 1012973 | C5: ST EG GATSU BALI | D5: 80.70 | E5: IBT 03 | F5: ST | G5: Denpasar | H5: REG 05 | I5: 4.05 | J5: =_xlfn.XLOOKUP(C5,Master!C:C,Master!B:B) -> 2121
A6: 1015480 | C6: ST EG CIKUPA TANGERANG | D6: 85.80 | E6: DKI 03 | F6: ST | G6: Tangerang | H6: REG 01 | I6: 4.3 | J6: =_xlfn.XLOOKUP(C6,Master!C:C,Master!B:B) -> #N/A
A7: 1013049 | C7: ST EG OL MALANG | D7: 88.63 | E7: JATIM 02 | F7: ST | G7: Malang | H7: REG 04 | I7: 4.45 | J7: =_xlfn.XLOOKUP(C7,Master!C:C,Master!B:B) -> 2029
A8: 1013301 | C8: ST EG NGALIYAN SEMARANG | D8: 79.74 | E8: JATENG 02 | F8: ST | G8: Semarang | H8: REG 03 | I8: 4 | J8: =_xlfn.XLOOKUP(C8,Master!C:C,Master!B:B) -> 2224
A9: 1013776 | C9: ST EG PASAR MINGGU | D9: 78.08 | E9: DKI 01 | F9: ST | G9: Jakarta Selatan | H9: REG 01 | I9: 3.9 | J9: =_xlfn.XLOOKUP(C9,Master!C:C,Master!B:B) -> 2339
A10: 1013209 | C10: SH EG MALL SKA PEKANBARU | D10: 87.32 | E10: SUM 02 | F10: SH | G10: Pekanbaru | H10: REG 03 | I10: 4.35 | J10: =_xlfn.XLOOKUP(C10,Master!C:C,Master!B:B) -> 5052
A11: 1014465 | C11: ST EG CIBARUSAH | D11: 76.94 | E11: DKI 02 | F11: ST | G11: Bekasi | H11: REG 01 | I11: 3.85 | J11: =_xlfn.XLOOKUP(C11,Master!C:C,Master!B:B) -> 2172
A12: 1013766 | C12: ST EG KEMANG | D12: 74.05 | E12: DKI 01 | F12: ST | G12: Jakarta Selatan | H12: REG 01 | I12: 3.7 | J12: =_xlfn.XLOOKUP(C12,Master!C:C,Master!B:B) -> 2212
A13: 1013719 | C13: ST EG TULUNG AGUNG | D13: 69.63 | E13: JATIM 02 | F13: ST | G13: Tulungagung | H13: REG 04 | I13: 3.5 | J13: =_xlfn.XLOOKUP(C13,Master!C:C,Master!B:B) -> 2099
A14: 1014335 | C14: ST EG NGAWI | D14: 86.52 | E14: JATIM 03 | F14: ST | G14: Ngawi | H14: REG 04 | I14: 4.35 | J14: =_xlfn.XLOOKUP(C14,Master!C:C,Master!B:B) -> 2208
A15: 1013440 | C15: ST EG CANGGU BALI | D15: 82.61 | E15: IBT 03 | F15: ST | G15: Canggu | H15: REG 05 | I15: 4.15 | J15: =_xlfn.XLOOKUP(C15,Master!C:C,Master!B:B) -> 2332
A16: 1014011 | C16: ST EG SOLO BARU | D16: 76.60 | E16: JATENG 01 | F16: ST | G16: Kabupaten Sukoharjo | H16: REG 03 | I16: 3.85 | J16: =_xlfn.XLOOKUP(C16,Master!C:C,Master!B:B) -> 7014
A17: 1013401 | C17: SH EG MALL OLYMPIC GARDEN MALANG | D17: 77.00 | E17: JATIM 02 | F17: SH | G17: Malang | H17: REG 04 | I17: 3.85 | J17: =_xlfn.XLOOKUP(C17,Master!C:C,Master!B:B) -> 5042
A18: 1014125 | C18: ST EG PLUIT MUARA KARANG | D18: 96.88 | E18: DKI 01 | F18: ST | G18: Jakarta Utara | H18: REG 01 | I18: 4.85 | J18: =_xlfn.XLOOKUP(C18,Master!C:C,Master!B:B) -> 2337
A19: 1013398 | C19: ST EG MARPOYAN PEKANBARU | D19: 90.76 | E19: SUM 02 | F19: ST | G19: Pekanbaru | H19: REG 03 | I19: 4.55 | J19: =_xlfn.XLOOKUP(C19,Master!C:C,Master!B:B) -> 7041
A20: 1013450 | C20: ST EG KEPANJEN MALANG | D20: 98.19 | E20: JATIM 02 | F20: ST | G20: Malang | H20: REG 04 | I20: 4.9 | J20: =_xlfn.XLOOKUP(C20,Master!C:C,Master!B:B) -> 7008
... A54: 1013845 | C54: ST EG MARTADINATA MANADO | D54: 64.76 | E54: IBT 04 | F54: ST | G54: Manado | H54: REG 05 | I54: 3.25 | J54: =_xlfn.XLOOKUP(C54,Master!C:C,Master!B:B) -> 7037
A55: 1014004 | C55: ST EG BIREUEN ACEH | D55: 80.23 | E55: SUM 03 | F55: ST | G55: Bireuen | H55: REG 03 | I55: 4 | J55: =_xlfn.XLOOKUP(C55,Master!C:C,Master!B:B) -> 2279
A56: 1015977 | C56: ST EG SILIWANGI CIREBON | D56: 91.74 | E56: JABAR 03 | F56: ST | G56: Cirebon | H56: REG 02 | I56: 4.6 | J56: =_xlfn.XLOOKUP(C56,Master!C:C,Master!B:B) -> 2313
A57: 1013826 | C57: ST EG SUDIRMAN LUWUK | D57: 77.76 | E57: IBT 02 | F57: ST | G57: Banggai | H57: REG 05 | I57: 3.9 | J57: =_xlfn.XLOOKUP(C57,Master!C:C,Master!B:B) -> 2218
A58: 1013848 | C58: ST EG OL CIHAMPELAS BANDUNG | D58: 83.60 | E58: JABAR 01 | F58: ST | G58: Bandung | H58: REG 02 | I58: 4.2 | J58: =_xlfn.XLOOKUP(C58,Master!C:C,Master!B:B) -> 2004
A59: 1013858 | C59: ST EG OL CIPUTAT JAKARTA | D59: 75.79 | E59: DKI 03 | F59: ST | G59: Tangerang Selatan | H59: REG 01 | I59: 3.8 | J59: =_xlfn.XLOOKUP(C59,Master!C:C,Master!B:B) -> 2065
A60: 1013958 | C60: ST EG OL PALEMBANG | D60: 73.88 | E60: SUM 01 | F60: ST | G60: Palembang | H60: REG 02 | I60: 3.7 | J60: =_xlfn.XLOOKUP(C60,Master!C:C,Master!B:B) -> 2079
A61: 1013991 | C61: ST EG SLAMET RIYADI SAMARINDA | D61: 80.51 | E61: IBT 01 | F61: ST | G61: Samarinda | H61: REG 05 | I61: 4.05 | J61: =_xlfn.XLOOKUP(C61,Master!C:C,Master!B:B) -> 7023
A62: 1014015 | C62: ST EG OL SEMARANG | D62: 76.37 | E62: JATENG 02 | F62: ST | G62: Semarang | H62: REG 03 | I62: 3.8 | J62: =_xlfn.XLOOKUP(C62,Master!C:C,Master!B:B) -> 2032
A63: 1014026 | C63: ST EG OL KEMANGGISAN JAKARTA | D63: 89.96 | E63: DKI 01 | F63: ST | G63: Jakarta Barat | H63: REG 01 | I63: 4.5 | J63: =_xlfn.XLOOKUP(C63,Master!C:C,Master!B:B) -> 2135
A64: 1014018 | C64: ST EG DELISERDANG | D64: 96.63 | E64: SUM 03 | F64: ST | G64: Deli Serdang | H64: REG 03 | I64: 4.85 | J64: =_xlfn.XLOOKUP(C64,Master!C:C,Master!B:B) -> 7038
A65: 1014070 | C65: ST EG OL JATIBENING | D65: 81.64 | E65: DKI 02 | F65: ST | G65: Bekasi | H65: REG 01 | I65: 4.1 | J65: =_xlfn.XLOOKUP(C65,Master!C:C,Master!B:B) -> 2188
A66: 1014376 | C66: ST EG PENGAYOMAN MAKASAR | D66: 80.09 | E66: IBT 02 | F66: ST | G66: Makassar | H66: REG 05 | I66: 4 | J66: =_xlfn.XLOOKUP(C66,Master!C:C,Master!B:B) -> 2125
A67: 1014111 | C67: ST EG GRAND DEPOK CITY | D67: 80.13 | E67: DKI 04 | F67: ST | G67: Depok | H67: REG 01 | I67: 4 | J67: =_xlfn.XLOOKUP(C67,Master!C:C,Master!B:B) -> 2393
A68: 1014120 | C68: ST EG CITEUREUP BOGOR | D68: 95.12 | E68: DKI 04 | F68: ST | G68: Bogor | H68: REG 01 | I68: 4.75 | J68: =_xlfn.XLOOKUP(C68,Master!C:C,Master!B:B) -> 2240
A69: 1014062 | C69: ST EG CIPONDOH TANGERANG | D69: 84.70 | E69: DKI 03 | F69: ST | G69: Tangerang | H69: REG 01 | I69: 4.25 | J69: =_xlfn.XLOOKUP(C69,Master!C:C,Master!B:B) -> 2236
A70: 1014094 | C70: ST EG SUKAMTO PALEMBANG | D70: 82.40 | E70: SUM 01 | F70: ST | G70: Palembang | H70: REG 02 | I70: 4.1 | J70: =_xlfn.XLOOKUP(C70,Master!C:C,Master!B:B) -> #N/A
A71: 1014122 | C71: ST EG PATI | D71: 84.72 | E71: JATENG 02 | F71: ST | G71: Kabupaten Pati | H71: REG 03 | I71: 4.25 | J71: =_xlfn.XLOOKUP(C71,Master!C:C,Master!B:B) -> 7033
A72: 1014298 | C72: ST EG OL SLAMET RIYADI SOLO | D72: 69.57 | E72: JATENG 01 | F72: ST | G72: Surakarta | H72: REG 03 | I72: 3.5 | J72: =_xlfn.XLOOKUP(C72,Master!C:C,Master!B:B) -> 2053
A73: 1014332 | C73: ST EG FS BABARSARI YOGYAKARTA | D73: 68.93 | E73: JATENG 01 | F73: ST | G73: Yogyakarta | H73: REG 01 | I73: 3.45 | J73: =_xlfn.XLOOKUP(C73,Master!C:C,Master!B:B) -> 2040
...

Sheet Wave 1 2024
A1: Review number | B1: Survey report | C1: Short branch name | D1: Result | E1: Branch Area | F1: Jenis Toko | G1: Kota | H1: Regional | I1: KPI | J1: Site Code
A2: 992948 | C2: ST EG YUDANEGARA TASIKMALAYA | D2: 89.59 | E2: JABAR 03 | F2: ST | G2: Tasikmalaya | H2: REG 02 | I2: 4.5 | J2: =_xlfn.XLOOKUP(C2,Master!C:C,Master!B:B) -> 2301
A3: 990058 | C3: ST EG WONOSOBO | D3: 90.19 | E3: JATENG 02 | F3: ST | G3: Kabupaten Wonosobo | H3: REG 03 | I3: 4.5 | J3: =_xlfn.XLOOKUP(C3,Master!C:C,Master!B:B) -> 2113
A4: 993640 | C4: SH EG PLAZA ASIA TASIKMALAYA | D4: 88.95 | E4: JABAR 03 | F4: SH | G4: Tasikmalaya | H4: REG 02 | I4: 4.45 | J4: =_xlfn.XLOOKUP(C4,Master!C:C,Master!B:B) -> 5089
A5: 992235 | C5: ST EG BEKASI UTARA | D5: 86.86 | E5: DKI 02 | F5: ST | G5: Bekasi | H5: REG 01 | I5: 4.35 | J5: =_xlfn.XLOOKUP(C5,Master!C:C,Master!B:B) -> 7028
A6: 992458 | C6: ST EG BATANG | D6: 86.61 | E6: JATENG 02 | F6: ST | G6: Kabupaten Batang | H6: REG 01 | I6: 4.35 | J6: =_xlfn.XLOOKUP(C6,Master!C:C,Master!B:B) -> #N/A
A7: 991095 | C7: ST EG SUKOHARJO | D7: 87.37 | E7: JATENG 01 | F7: ST | G7: Sukoharjo | H7: REG 01 | I7: 4.35 | J7: =_xlfn.XLOOKUP(C7,Master!C:C,Master!B:B) -> #N/A
A8: 989936 | C8: ST EG LEMBANG | D8: 86.98 | E8: JABAR 04 | F8: ST | G8: Bandung | H8: REG 02 | I8: 4.35 | J8: =_xlfn.XLOOKUP(C8,Master!C:C,Master!B:B) -> 2305
A9: 993661 | C9: ST EG TENTARA PELAJAR TASIK | D9: 87.10 | E9: JABAR 03 | F9: ST | G9: Tasikmalaya | H9: REG 02 | I9: 4.35 | J9: =_xlfn.XLOOKUP(C9,Master!C:C,Master!B:B) -> 2168
A10: 993029 | C10: ST EG BLORA | D10: 86.54 | E10: JATENG 02 | F10: ST | G10: Kabupaten Blora | H10: REG 03 | I10: 4.35 | J10: =_xlfn.XLOOKUP(C10,Master!C:C,Master!B:B) -> 2276
A11: 992659 | C11: ST EG CITEUREUP BOGOR | D11: 85.66 | E11: DKI 04 | F11: ST | G11: Bogor | H11: REG 01 | I11: 4.3 | J11: =_xlfn.XLOOKUP(C11,Master!C:C,Master!B:B) -> 2240
A12: 992721 | C12: SH EG BIP BANDUNG | D12: 86.46 | E12: JABAR 01 | F12: SH | G12: Bandung | H12: REG 02 | I12: 4.3 | J12: =_xlfn.XLOOKUP(C12,Master!C:C,Master!B:B) -> 5000
A13: 989548 | C13: ST EG PATI | D13: 85.66 | E13: JATENG 02 | F13: ST | G13: Kabupaten Pati | H13: REG 03 | I13: 4.3 | J13: =_xlfn.XLOOKUP(C13,Master!C:C,Master!B:B) -> 7033
... A83: 990307 | C83: ST EG OL MALANG | D83: 81.13 | E83: JATIM 02 | F83: ST | G83: Malang | H83: REG 04 | I83: 4.05 | J83: =_xlfn.XLOOKUP(C83,Master!C:C,Master!B:B) -> 2029
A84: 992533 | C84: ST EG KBP BANDUNG | D84: 81 | E84: JABAR 04 | F84: ST | G84: Padalarang | H84: REG 02 | I84: 4.05 | J84: =_xlfn.XLOOKUP(C84,Master!C:C,Master!B:B) -> 2304
A85: 993070 | C85: ST EG JUANDA CIAMIS | D85: 81.34 | E85: JABAR 03 | F85: ST | G85: Kabupaten Ciamis | H85: REG 02 | I85: 4.05 | J85: =_xlfn.XLOOKUP(C85,Master!C:C,Master!B:B) -> 2220
A86: 992639 | C86: ST EG SILIWANGI CIREBON | D86: 80.07 | E86: JABAR 03 | F86: ST | G86: Cirebon | H86: REG 02 | I86: 4 | J86: =_xlfn.XLOOKUP(C86,Master!C:C,Master!B:B) -> 2313
A87: 992648 | C87: ST EG PADJ BOGOR | D87: 79.52 | E87: DKI 04 | F87: ST | G87: Bogor | H87: REG 01 | I87: 4 | J87: =_xlfn.XLOOKUP(C87,Master!C:C,Master!B:B) -> 2008
A88: 990674 | C88: ST EG BEKASI TIMUR | D88: 80.05 | E88: DKI 02 | F88: ST | G88: Bekasi | H88: REG 01 | I88: 4 | J88: =_xlfn.XLOOKUP(C88,Master!C:C,Master!B:B) -> 2043
A89: 991421 | C89: ST EG MAJAPAHIT SEMARANG | D89: 80.37 | E89: JATENG 02 | F89: ST | G89: Semarang | H89: REG 03 | I89: 4 | J89: =_xlfn.XLOOKUP(C89,Master!C:C,Master!B:B) -> 2108
A90: 989505 | C90: SH EG KOTA KASABLANCA JAKARTA | D90: 79.72 | E90: DKI 01 | F90: SH | G90: Jakarta Selatan | H90: REG 01 | I90: 4 | J90: =_xlfn.XLOOKUP(C90,Master!C:C,Master!B:B) -> 5026
A91: 991384 | C91: ST EG OL BOGOR | D91: 79.66 | E91: DKI 04 | F91: ST | G91: Bogor | H91: REG 01 | I91: 4 | J91: =_xlfn.XLOOKUP(C91,Master!C:C,Master!B:B) -> 2013
A92: 991249 | C92: ST EG TALANGBANJAR JAMBI | D92: 79.95 | E92: SUM 01 | F92: ST | G92: Jambi | H92: REG 02 | I92: 4 | J92: =_xlfn.XLOOKUP(C92,Master!C:C,Master!B:B) -> #N/A
A93: 992094 | C93: ST EG NGAWI | D93: 80.08 | E93: JATIM 03 | F93: ST | G93: Ngawi | H93: REG 04 | I93: 4 | J93: =_xlfn.XLOOKUP(C93,Master!C:C,Master!B:B) -> 2208
A94: 991048 | C94: SH EG CITRALAND SEMARANG | D94: 79.55 | E94: JATENG 02 | F94: SH | G94: Semarang | H94: REG 03 | I94: 4 | J94: =_xlfn.XLOOKUP(C94,Master!C:C,Master!B:B) -> 5056
A95: 989808 | C95: ST EG CIKARANG | D95: 79.62 | E95: DKI 02 | F95: ST | G95: Bekasi | H95: REG 01 | I95: 4 | J95: =_xlfn.XLOOKUP(C95,Master!C:C,Master!B:B) -> 2223
A96: 993129 | C96: ST EG MERUYA JAKARTA | D96: 79.76 | E96: DKI 01 | F96: ST | G96: Jakarta Barat | H96: REG 01 | I96: 4 | J96: =_xlfn.XLOOKUP(C96,Master!C:C,Master!B:B) -> 2310
A97: 991942 | C97: ST EG CINERE DEPOK | D97: 80.07 | E97: DKI 04 | F97: ST | G97: Depok | H97: REG 01 | I97: 4 | J97: =_xlfn.XLOOKUP(C97,Master!C:C,Master!B:B) -> 2187
... A100: 992084 | C100: ST EG KEBUMEN | D100: 80.32 | E100: JATENG 01 | F100: ST | G100: Kebumen | H100: REG 03 | I100: 4 | J100: =_xlfn.XLOOKUP(C100,Master!C:C,Master!B:B) -> 2152
A101: 992907 | C101: SH AEON MALL SENTUL | D101: 78.74 | E101: DKI 04 | F101: SH | G101: Bogor | H101: REG 01 | I101: 3.95 | J101: =_xlfn.XLOOKUP(C101,Master!C:C,Master!B:B) -> 5159
A102: 992007 | C102: SH EG MEDAN FAIR | D102: 79.27 | E102: SUM 03 | F102: SH | G102: Medan | H102: REG 03 | I102: 3.95 | J102: =_xlfn.XLOOKUP(C102,Master!C:C,Master!B:B) -> 5045
A103: 990955 | C103: ST EG OL CILEDUG JAKARTA | D103: 78.68 | E103: DKI 03 | F103: ST | G103: Tangerang | H103: REG 01 | I103: 3.95 | J103: =_xlfn.XLOOKUP(C103,Master!C:C,Master!B:B) -> 2116
A104: 992080 | C104: ST EG CIANJUR | D104: 79.07 | E104: JABAR 04 | F104: ST | G104: Kabupaten Cianjur | H104: REG 02 | I104: 3.95 | J104: =_xlfn.XLOOKUP(C104,Master!C:C,Master!B:B) -> 2184
A105: 991854 | C105: ST EG SANGATTA | D105: 79.09 | E105: IBT 01 | F105: ST | G105: Sangatta Utara | H105: REG 05 | I105: 3.95 | J105: =_xlfn.XLOOKUP(C105,Master!C:C,Master!B:B) -> 2263
A106: 992631 | C106: ST EG SUCI | D106: 78.92 | E106: JABAR 02 | F106: ST | G106: Bandung | H106: REG 02 | I106: 3.95 | J106: =_xlfn.XLOOKUP(C106,Master!C:C,Master!B:B) -> 2387
A107: 992592 | C107: ST EG PLAJU PALEMBANG | D107: 78.80 | E107: SUM 01 | F107: ST | G107: Palembang | H107: REG 02 | I107: 3.95 | J107: =_xlfn.XLOOKUP(C107,Master!C:C,Master!B:B) -> 2102
A108: 992579 | C108: ST EG JATI ASIH BEKASI | D108: 79.33 | E108: DKI 02 | F108: ST | G108: Bekasi | H108: REG 01 | I108: 3.95 | J108: =_xlfn.XLOOKUP(C108,Master!C:C,Master!B:B) -> 2178
A109: 992588 | C109: ST EG GRAND DEPOK CITY | D109: 78.80 | E109: DKI 04 | F109: ST | G109: Depok | H109: REG 01 | I109: 3.95 | J109: =_xlfn.XLOOKUP(C109,Master!C:C,Master!B:B) -> 2393
A110: 992908 | C110: ST EG GENTENG BANYUWANGI | D110: 78.87 | E110: JATIM 02 | F110: ST | G110: Banyuwangi | H110: REG 04 | I110: 3.95 | J110: =_xlfn.XLOOKUP(C110,Master!C:C,Master!B:B) -> 2215
A111: 993281 | C111: ST EG BAU BAU | D111: 79.47 | E111: IBT 02 | F111: ST | G111: Baubau | H111: REG 05 | I111: 3.95 | J111: =_xlfn.XLOOKUP(C111,Master!C:C,Master!B:B) -> 2243
...

Sheet Master
A1: Review number | B1: Site | C1: Short branch name | D1: Result | E1: Branch Area | F1: Jenis Toko | G1: Kota | H1: Regional | I1: KPI
A2: 1056145 | B2: 2269 | C2: ST EG KALIMALANG JAKTIM | D2: 80.8 | E2: DKI 01 | F2: ST | G2: Jakarta Timur | H2: REG 01 | I2: 4.05
A3: 1055690 | B3: 7017 | C3: ST EG PURWOREJO | D3: 72.19 | E3: JATENG 01 | F3: ST | G3: Kabupaten Purworejo | H3: REG 01 | I3: 3.6
A4: 1056015 | B4: 2135 | C4: ST EG OL KEMANGGISAN JAKARTA | D4: 65.93 | E4: DKI 01 | F4: ST | G4: Jakarta Barat | H4: REG 01 | I4: 3.3
A5: 1055760 | B5: 2325 | C5: ST EG TEHOK JAMBI | D5: 74.77 | E5: SUM 01 | F5: ST | G5: Jambi | H5: REG 02 | I5: 3.75
A6: 1055619 | B6: 2219 | C6: ST EG SURABAYA BARAT | D6: 67.26 | E6: JATIM 01 | F6: ST | G6: Surabaya | H6: REG 03 | I6: 3.35
A7: 1059090 | B7: 7040 | C7: ST EG BANDA ACEH | D7: 88.9 | E7: SUM 02 | F7: ST | G7: Banda Aceh | H7: REG 02 | I7: 4.45
A8: 1056046 | B8: 2013 | C8: ST EG OL BOGOR | D8: 75.39 | E8: DKI 02 | F8: ST | G8: Bogor | H8: REG 01 | I8: 3.75
A9: 1055857 | B9: 2225 | C9: ST EG ANTASARI LAMPUNG | D9: 83.01 | E9: SUM 01 | F9: ST | G9: Bandar Lampung | H9: REG 02 | I9: 4.15
A10: 1055707 | B10: 7032 | C10: ST EG CIMAHI UTARA | D10: 80.72 | E10: JABAR 01 | F10: ST | G10: Cimahi | H10: REG 02 | I10: 4.05
A11: 1057277 | B11: 5148 | C11: SH EG PARIS VAN JAVA BANDUNG | D11: 85.41 | E11: JABAR 01 | F11: SH | G11: Bandung | H11: REG 02 | I11: 4.25
A12: 1056034 | B12: 2398 | C12: ST EG OL MANYAR 2 | D12: 72.74 | E12: JATIM 01 | F12: ST | G12: Surabaya | H12: REG 03 | I12: 3.65
A13: 1056194 | B13: 5025 | C13: SH EG ATRIUM JAKARTA | D13: 82.97 | E13: DKI 01 | F13: SH | G13: Jakarta Pusat | H13: REG 01 | I13: 4.15
... A277: 1060604 | B277: 2354 | C277: ST EG MUARA BUNGO | D277: 58.14 | E277: SUM 01 | F277: ST | G277: Jambi | H277: REG 02 | I277: 2.9
A278: Average | D278: 78.95 | I278: 3.95
